Workbook

Sheet 1. Maint Account
B1: Sl.No | C1: Date of Invoice | D1: Invoice Number | E1: Payment Date | F1: Service Month | G1: Quarter | H1: Vendor Name | I1: Particulars | J1: Classification-1 | K1: Taxable | L1: % | M1: Invoice Value | N1: TDS | O1: Net Paid | P1: Nature | Q1: Classification | T1: Total Expense Paid
B2: 1 | E2: 45751 | F2: 45748 | G2: Q4 FY 24-25 | H2: Mukajjar Smarttech India | I2: 30% payment for removal of chamber cover | J2: RWH Works | K2: 1568661 | M2: 1568661 | O2: 470598 | P2: Capex | Q2: Civil & Lifts | T2: =N2+O2 -> 470598
B3: 2 | C3: 25-03-2025 | D3: Quotation | E3: 45751 | F3: 45748 | G3: Q4 FY 24-25 | H3: S R Office Suppliers | I3: Sodium hypochlorites,test kit,waste cloth | J3: STP- Consumables | K3: 34460 | L3: 6164 | M3: 40624 | O3: 40624 | P3: Ad-Hoc | Q3: Water & Sewage | T3: =N3+O3 -> 40624
B4: 3 | D4: Quotation | E4: 45755 | F4: 45748 | G4: Q1 | H4: Blaze Design Tech | I4: 30% advance payment forSupply and installation of 30 Zone | J4: Fire Alarm Installation | K4: 637170 | M4: 637170 | O4: 191151 | P4: Capex | Q4: Safety & Security | T4: =N4+O4 -> 191151
B5: 4 | C5: 45745 | D5: 226/24-25 | E5: 45755 | F5: 45748 | G5: Q1 | H5: Mukajjar Smarttech India | I5: Supply and providing of new granite door seal | J5: Purchase of Granite | K5: 29700 | L5: 5346 | M5: 20196 | N5: 594 | O5: 19602 | P5: Ad-Hoc | Q5: Civil & Lifts | T5: =N5+O5 -> 20196
B6: 5 | C6: 45661 | D6: PTI202526-00914 | E6: 45755 | F6: 45748 | G6: Q1 | H6: Parivom Technologies Pvt Ltd | I6: Automated Gate and security solution | J6: Park-plus Services | K6: 125100 | L6: 22518 | M6: 147618 | N6: 2502 | O6: 145116 | P6: Capex | Q6: Safety & Security | T6: =N6+O6 -> 147618
B7: 6 | C7: 45661 | D7: KLKA2526-04055 | E7: 45755 | F7: 45717 | G7: Q4 FY 24-25 | H7: Kre38 Labs pvt ltd | I7: Waltr A monthly subscription | J7: Water Level Meters | K7: 8980 | L7: 1616 | M7: 10596 | N7: 180 | O7: 10417 | P7: Operating | Q7: Water & Sewage | T7: =N7+O7 -> 10597
B8: 7 | C8: 21-03-2025 | D8: OP/24-25/1643 | E8: 45755 | F8: 45748 | G8: Q1 | H8: Office point | I8: Box file YES955,Cello tape | J8: Housekeeping Consumables | K8: 27262 | L8: 3914 | M8: 31176 | O8: 31176 | P8: Ad-Hoc | Q8: Estate Management | T8: =N8+O8 -> 31176
B9: 8 | C9: 45661 | D9: IAC-17/2 | E9: 45755 | F9: 45717 | G9: Q4 FY 24-25 | H9: Think Thanx | I9: CCTV AMC charges for the month of March 2025 | J9: CCTV Maint | K9: 7500 | L9: 1350 | M9: 8850 | N9: 75 | O9: 8775 | P9: Operating | Q9: Safety & Security | T9: =N9+O9 -> 8850
B10: 9 | C10: 31-03-2025 | D10: 3015 | E10: 45757 | F10: 45717 | G10: Q4 FY 24-25 | H10: Sree Sai Ganesh Minerals | I10: 20L Water can | J10: Drinking Water Can | K10: 27636 | L10: 3316 | M10: 30952 | O10: 30952 | P10: Operating | Q10: Water & Sewage | T10: =N10+O10 -> 30952
B11: 10 | C11: 14-03-2025 | D11: OP/24-25/1618 | E11: 45757 | F11: 45748 | G11: Q1 | H11: Office Point | I11: Garbage Bag extra large pearl 40MIC | J11: Housekeeping Consumables | K11: 76968 | L11: 12739 | M11: 89707 | O11: 89707 | P11: Ad-Hoc | Q11: Estate Management | T11: =N11+O11 -> 89707
B12: 11 | C12: 45720 | D12: 24 | E12: 45757 | F12: 45748 | G12: Q1 | H12: Chandu Enterprises | I12: Remaining 50% for Material shade net | J12: Shade Net | K12: 14880 | M12: 14880 | O12: 7440 | P12: Ad-Hoc | Q12: Estate Management | T12: =N12+O12 -> 7440
B13: 12 | C13: 30-3-2025 | D13: 59 | E13: 45757 | F13: 45717 | G13: Q4 FY 24-25 | H13: Sri Venkateshwara Enterprises | I13: Charges towards cleaning garbage for the month of March | J13: Garbage Collection | K13: 95000 | L13: 17100 | M13: 112100 | N13: 950 | O13: 111150 | P13: Operating | Q13: Housekeeping & Waste | T13: =N13+O13 -> 112100
B14: 13 | C14: 45751 | D14: VS4-2025-26/014 | E14: 45757 | F14: 45717 | G14: Q4 FY 24-25 | H14: VS4 | I14: Security guard | J14: Security Management Fees | K14: 156850 | L14: 28233 | M14: 185083 | N14: 3137 | O14: 181946 | P14: Operating | Q14: Safety & Security | T14: =N14+O14 -> 185083
B15: 14 | C15: 45751 | D15: VS4-2025-26/013 | E15: 45757 | F15: 45717 | G15: Q4 FY 24-25 | H15: VS4 | I15: Fire Officer | J15: Security Management Fees | K15: 42233 | L15: 7602 | M15: 49835 | N15: 844.66 | O15: 48990 | P15: Operating | Q15: Safety & Security | T15: =N15+O15 -> 49834.66
B16: 15 | C16: 45751 | D16: VS4-2025-26/012 | E16: 45757 | F16: 45717 | G16: Q4 FY 24-25 | H16: VS4 | I16: security officer,supervisor,guard,CCTV Operator | J16: Security Management Fees | K16: 1590902 | L16: 286362 | M16: 1877264 | N16: 31818.03 | O16: 1845446 | P16: Operating | Q16: Safety & Security | T16: =N16+O16 -> 1877264
B17: 16 | C17: 28-03-2025 | D17: 222/24-25 | E17: 45757 | F17: 45748 | G17: Q1 | H17: Mukajjar Smarttech India | I17: West gate entry and exit,Amber block entry,east gate entry and exit | J17: West gate Entry and Exit Civil Works | K17: 96404 | L17: 17353 | M17: 113757 | N17: 1928.08 | O17: 111829 | P17: Capex | Q17: Civil & Lifts | T17: =N17+O17 -> 113757.08
B18: 17 | D18: Quotation | E18: 45757 | F18: 45748 | G18: Q1 | H18: Septron Machinaries | I18: 50% Advance forMulti disc screw press model-Blue STP Screw press system supply & Installation | J18: Screw Press Machine for STP-Blue | K18: 505000 | L18: 90900 | M18: 595900 | O18: 297950 | P18: Capex | Q18: Water & Sewage | T18: =N18+O18 -> 297950
B19: 18 | C19: 25-03-2025 | D19: 1438 | E19: 45763 | F19: 45717 | G19: Q4 FY 24-25 | H19: Genex Utility & Management | I19: Operation and maintenance charges | J19: STP/WTP Maint | K19: 352880 | L19: 63518 | M19: 416398 | N19: 7058 | O19: 409341 | P19: Operating | Q19: Water & Sewage | T19: =N19+O19 -> 416399
B20: 19 | C20: 14-04-2025 | D20: 19286 | E20: 45763 | F20: 45748 | G20: Q1 | H20: Sai suchith pest control | I20: Pyndor,fogging gas can | J20: Pest control Consumables | K20: 10590 | L20: 1906 | M20: 12496 | O20: 12496 | P20: Operating | Q20: Housekeeping & Waste | T20: =N20+O20 -> 12496
B21: 20 | C21: 45965 | E21: 45763 | F21: 45748 | G21: Q1 | H21: Balaji electricals and lights gallery | I21: Core cable | J21: Electrical Items | K21: 22340 | L21: 4021 | M21: 26361 | O21: 26361 | P21: Ad-Hoc | Q21: Electrical | T21: =N21+O21 -> 26361
B22: 24 | C22: 45964 | D22: Quotation | E22: 45768 | F22: 45748 | G22: Q1 | H22: Contrast Engineering Works | I22: 50% Advance for Donation Box Fabrication | J22: Fabrication - Donation Box | K22: 21000 | L22: 3780 | M22: 24780 | O22: 12390 | P22: Ad-Hoc | Q22: Estate Management | T22: =N22+O22 -> 12390
B23: 25 | C23: 14-04-2025 | D23: OP/25-26/016 | E23: 45768 | F23: 45748 | G23: Q1 | H23: Office Point | I23: Garbage Bag extra large, Mopstick metal rod | J23: Housekeeping Consumables | K23: 75024 | L23: 12687 | M23: 87711 | O23: 87711 | P23: Ad-Hoc | Q23: Estate Management | T23: =N23+O23 -> 87711
B24: 26 | C24: 15-04-2025 | D24: 26 | E24: 45768 | F24: 45748 | G24: Q1 | H24: Chandu enterprises | I24: Garware net | J24: Net | K24: 7200 | M24: 7200 | O24: 7200 | P24: Ad-Hoc | Q24: Estate Management | T24: =N24+O24 -> 7200
B25: 27 | C25: 45965 | D25: 22 | E25: 45768 | F25: 45748 | G25: Q1 | H25: Srinivas Agro Kendra | I25: Monocil,chorophyros,Tenget | J25: Landscaping Consumables | K25: 10510 | L25: 1892 | M25: 12402 | O25: 12402 | P25: Operating | Q25: Landscaping & ERT | T25: =N25+O25 -> 12402
B26: 28 | C26: 45965 | D26: 507 | E26: 45768 | F26: 45748 | G26: Q1 | H26: Srinivas Agro Kendra | I26: Cocopit | J26: Landscaping Consumables | K26: 3298 | M26: 3298 | O26: 3298 | P26: Operating | Q26: Landscaping & ERT | T26: =N26+O26 -> 3298
B27: 29 | C27: 14-04-2025 | D27: INV-25-26/0002 | E27: 45768 | F27: 45748 | G27: Q1 | H27: Agarwal & Shetty | I27: Book keeping charges | J27: Bookkeeping Services | K27: 89888 | L27: 16180 | M27: 106068 | N27: 8989 | O27: 97079 | P27: Operating | Q27: Finance & Accounts | T27: =N27+O27 -> 106068
B28: 30 | C28: 18-04-2025 | D28: 29 | E28: 45768 | F28: 45748 | G28: Q1 | H28: Harish Trading and Engineering | I28: Crimson Borewell Starter with auto phase | J28: Borewell | K28: 22010 | L28: 3962 | M28: 25972 | O28: 25972 | P28: Capex | Q28: Water & Sewage | T28: =N28+O28 -> 25972
B29: 31 | C29: 26-03-2025 | D29: Quotation | E29: 45768 | F29: 45748 | G29: Q1 | H29: Elon Facade | I29: 50% Advance for Eyebolt Fixing | J29: Eyebolt Fixing | K29: 15000 | M29: 15000 | O29: 7500 | P29: Ad-Hoc | Q29: Estate Management | T29: =N29+O29 -> 7500
B30: 32 | C30: 17-04-2025 | E30: 45768 | F30: 45748 | G30: Q1 | H30: Poonam Hardware & Electricals | I30: ACC Cement | J30: Plumbing Consumables | K30: 5000 | M30: 5000 | O30: 5000 | P30: Ad-Hoc | Q30: Water & Sewage | T30: =N30+O30 -> 5000
B31: 33 | C31: 19-04-2025 | E31: 45768 | F31: 45748 | G31: Q1 | H31: Poonam Hardware & Electricals | I31: Plumbing Material | J31: Plumbing Consumables | K31: 7300 | M31: 7300 | O31: 7300 | P31: Ad-Hoc | Q31: Water & Sewage | T31: =N31+O31 -> 7300
B32: 34 | E32: 45768 | F32: 45748 | G32: Q1 | H32: Mukajjar Smarttech India | I32: Crimson and Amber RWH Works | J32: RWH Works | K32: 1898631 | L32: 341754 | M32: 2240385 | O32: 653654 | P32: Capex | Q32: Civil & Lifts | T32: =N32+O32 -> 653654
B33: 35 | C33: 19-04-2025 | E33: 45770 | F33: 45748 | G33: Q1 | H33: Balaji electricals and lights gallery | I33: Silk cable | J33: Electrical Items | K33: 974 | L33: 176 | M33: 1150 | O33: 1150 | P33: Ad-Hoc | Q33: Electrical | T33: =N33+O33 -> 1150
B34: 36 | C34: 16-04-2025 | D34: 1924 | E34: 45770 | F34: 45748 | G34: Q1 | H34: Sri Maruthi Septic Cleaners | I34: Sewage sludge disposal from Blue Block STP | J34: STP- Sludge Removal | K34: 26650 | L34: 4797 | M34: 31447 | O34: 31447 | P34: Ad-Hoc | Q34: Water & Sewage | T34: =N34+O34 -> 31447
B35: 37 | C35: 13-04-2025 | E35: 45773 | F35: 45748 | G35: Q1 | H35: Balaji electricals and lights gallery | I35: Pipe, Bend, Core cable | J35: Electrical Items | K35: 4579 | L35: 824 | M35: 5403 | O35: 5403 | P35: Ad-Hoc | Q35: Electrical | T35: =N35+O35 -> 5403
B36: 38 | C36: 13-04-2025 | D36: 4 | E36: 45773 | F36: 45748 | G36: Q1 | H36: Moksha Distributors | I36: UP & Down Down light | J36: Electrical Items | K36: 4695 | L36: 845 | M36: 5540 | O36: 5540 | P36: Ad-Hoc | Q36: Electrical | T36: =N36+O36 -> 5540
B37: 39 | C37: 23-04-2025 | D37: IV-25-007 | E37: 45773 | F37: 45748 | G37: Q1 | H37: Elon Facade | I37: Remaining 50% for eye bolt fixing | J37: Eyebolt Fixing | K37: 15000 | L37: 2700 | M37: 17700 | O37: 10200 | P37: Ad-Hoc | Q37: Estate Management | T37: =N37+O37 -> 10200
B38: 40 | C38: 23-04-2025 | D38: Quotation | E38: 45773 | F38: 45748 | G38: Q1 | H38: Karnataka Motors Rewinding Co | I38: 50% Advance for lubi make monoblock pump Motor | J38: Motor Pump Service | K38: 26520 | M38: 26520 | O38: 13260 | P38: Ad-Hoc | Q38: Water & Sewage | T38: =N38+O38 -> 13260
B39: 41 | C39: 19-04-2025 | D39: 5 | E39: 45773 | F39: 45748 | G39: Q1 | H39: Om Enterprises | I39: Green protection Mesh | J39: Net | K39: 7195 | L39: 1295 | M39: 8490 | O39: 8490 | P39: Ad-Hoc | Q39: Housekeeping & Waste | T39: =N39+O39 -> 8490
B40: 42 | C40: 45775 | E40: 45775 | F40: 45748 | G40: Q1 | H40: ICICI | I40: Bank Charges | J40: Bank Charges | K40: 10 | L40: 2 | M40: 12 | O40: 12 | P40: Operating | Q40: Finance & Accounts | T40: =N40+O40 -> 12
...

Sheet OPEX Budget
A1: Nature | B1: Amount | C1: Quarter
A2: Water & Sewage | B2: 5108241 | C2: Q3 | P2: Q1 | Q2: Q2 | R2: Q3 | S2: Q4
A3: Civil & Lifts | B3: 1613900.1 | C3: Q3 | P3: Operating
A4: Electrical | B4: 4941421.3 | C4: Q3 | O4: Civil & Lifts | P4: =SUMIFS('1. Maint Account'!T:T,'1. Maint Account'!Q:Q,'OPEX Budget'!O4,'1. Maint Account'!P:P,'OPEX Budget'!$P$3,'1. Maint Account'!G:G,"Q1") -> 1502437.8 | Q4: =SUMIFS('1. Maint Account'!T:T,'1. Maint Account'!Q:Q,'OPEX Budget'!O4,'1. Maint Account'!P:P,'OPEX Budget'!$P$3,'1. Maint Account'!G:G,"Q2") -> 1423952.3 | R4: =SUMIFS('1. Maint Account'!T:T,'1. Maint Account'!Q:Q,'OPEX Budget'!O4,'1. Maint Account'!P:P,'OPEX Budget'!$P$3,'1. Maint Account'!G:G,"Q3") -> 867538.88
A5: Housekeeping & Waste | B5: 3564038.2 | C5: Q3 | O5: Water & Sewage | P5: =SUMIFS('1. Maint Account'!T:T,'1. Maint Account'!Q:Q,'OPEX Budget'!O5,'1. Maint Account'!P:P,'OPEX Budget'!$P$3,'1. Maint Account'!G:G,"Q1") -> 2209323.6 | Q5: =SUMIFS('1. Maint Account'!T:T,'1. Maint Account'!Q:Q,'OPEX Budget'!O5,'1. Maint Account'!P:P,'OPEX Budget'!$P$3,'1. Maint Account'!G:G,"Q2") -> 2156778.5 | R5: =SUMIFS('1. Maint Account'!T:T,'1. Maint Account'!Q:Q,'OPEX Budget'!O5,'1. Maint Account'!P:P,'OPEX Budget'!$P$3,'1. Maint Account'!G:G,"Q3") -> 1441060.8
A6: ClubHouse | B6: 86939.788 | C6: Q3 | O6: Safety & Security | P6: =SUMIFS('1. Maint Account'!T:T,'1. Maint Account'!Q:Q,'OPEX Budget'!O6,'1. Maint Account'!P:P,'OPEX Budget'!$P$3,'1. Maint Account'!G:G,"Q1") -> 6553327.7 | Q6: =SUMIFS('1. Maint Account'!T:T,'1. Maint Account'!Q:Q,'OPEX Budget'!O6,'1. Maint Account'!P:P,'OPEX Budget'!$P$3,'1. Maint Account'!G:G,"Q2") -> 6742150.8 | R6: =SUMIFS('1. Maint Account'!T:T,'1. Maint Account'!Q:Q,'OPEX Budget'!O6,'1. Maint Account'!P:P,'OPEX Budget'!$P$3,'1. Maint Account'!G:G,"Q3") -> 4106979
A7: Safety & Security | B7: 7311042.3 | C7: Q3 | O7: Estate Management | P7: =SUMIFS('1. Maint Account'!T:T,'1. Maint Account'!Q:Q,'OPEX Budget'!O7,'1. Maint Account'!P:P,'OPEX Budget'!$P$3,'1. Maint Account'!G:G,"Q1") -> 1367948.8 | Q7: =SUMIFS('1. Maint Account'!T:T,'1. Maint Account'!Q:Q,'OPEX Budget'!O7,'1. Maint Account'!P:P,'OPEX Budget'!$P$3,'1. Maint Account'!G:G,"Q2") -> 1060973.4 | R7: =SUMIFS('1. Maint Account'!T:T,'1. Maint Account'!Q:Q,'OPEX Budget'!O7,'1. Maint Account'!P:P,'OPEX Budget'!$P$3,'1. Maint Account'!G:G,"Q3") -> 1163769.9
A8: Landscaping & ERT | B8: 1747775.6 | C8: Q3 | O8: Housekeeping & Waste | P8: =SUMIFS('1. Maint Account'!T:T,'1. Maint Account'!Q:Q,'OPEX Budget'!O8,'1. Maint Account'!P:P,'OPEX Budget'!$P$3,'1. Maint Account'!G:G,"Q1") -> 2857521.4 | Q8: =SUMIFS('1. Maint Account'!T:T,'1. Maint Account'!Q:Q,'OPEX Budget'!O8,'1. Maint Account'!P:P,'OPEX Budget'!$P$3,'1. Maint Account'!G:G,"Q2") -> 2559429.2 | R8: =SUMIFS('1. Maint Account'!T:T,'1. Maint Account'!Q:Q,'OPEX Budget'!O8,'1. Maint Account'!P:P,'OPEX Budget'!$P$3,'1. Maint Account'!G:G,"Q3") -> 2060479.4
A9: Estate Management | B9: 1956374.4 | C9: Q3 | O9: Electrical | P9: =SUMIFS('1. Maint Account'!T:T,'1. Maint Account'!Q:Q,'OPEX Budget'!O9,'1. Maint Account'!P:P,'OPEX Budget'!$P$3,'1. Maint Account'!G:G,"Q1") -> 3136437.4 | Q9: =SUMIFS('1. Maint Account'!T:T,'1. Maint Account'!Q:Q,'OPEX Budget'!O9,'1. Maint Account'!P:P,'OPEX Budget'!$P$3,'1. Maint Account'!G:G,"Q2") -> 3860591.2 | R9: =SUMIFS('1. Maint Account'!T:T,'1. Maint Account'!Q:Q,'OPEX Budget'!O9,'1. Maint Account'!P:P,'OPEX Budget'!$P$3,'1. Maint Account'!G:G,"Q3") -> 2363576
A10: Finance & Accounts | B10: 343301.96 | C10: Q3 | O10: Landscaping & ERT | P10: =SUMIFS('1. Maint Account'!T:T,'1. Maint Account'!Q:Q,'OPEX Budget'!O10,'1. Maint Account'!P:P,'OPEX Budget'!$P$3,'1. Maint Account'!G:G,"Q1") -> 1862731.4 | Q10: =SUMIFS('1. Maint Account'!T:T,'1. Maint Account'!Q:Q,'OPEX Budget'!O10,'1. Maint Account'!P:P,'OPEX Budget'!$P$3,'1. Maint Account'!G:G,"Q2") -> 1582255 | R10: =SUMIFS('1. Maint Account'!T:T,'1. Maint Account'!Q:Q,'OPEX Budget'!O10,'1. Maint Account'!P:P,'OPEX Budget'!$P$3,'1. Maint Account'!G:G,"Q3") -> 1091180.6
A11: Total | B11: =SUM(B2:B10) -> 26673035 | C11: Q3 | O11: Finance & Accounts | P11: =SUMIFS('1. Maint Account'!T:T,'1. Maint Account'!Q:Q,'OPEX Budget'!O11,'1. Maint Account'!P:P,'OPEX Budget'!$P$3,'1. Maint Account'!G:G,"Q1") -> 468239.8 | Q11: =SUMIFS('1. Maint Account'!T:T,'1. Maint Account'!Q:Q,'OPEX Budget'!O11,'1. Maint Account'!P:P,'OPEX Budget'!$P$3,'1. Maint Account'!G:G,"Q2") -> 424531.28 | R11: =SUMIFS('1. Maint Account'!T:T,'1. Maint Account'!Q:Q,'OPEX Budget'!O11,'1. Maint Account'!P:P,'OPEX Budget'!$P$3,'1. Maint Account'!G:G,"Q3") -> 212171.24
O12: ClubHouse | P12: =SUMIFS('1. Maint Account'!T:T,'1. Maint Account'!Q:Q,'OPEX Budget'!O12,'1. Maint Account'!P:P,'OPEX Budget'!$P$3,'1. Maint Account'!G:G,"Q1") -> 138303.13 | Q12: =SUMIFS('1. Maint Account'!T:T,'1. Maint Account'!Q:Q,'OPEX Budget'!O12,'1. Maint Account'!P:P,'OPEX Budget'!$P$3,'1. Maint Account'!G:G,"Q2") -> 84200.932 | R12: =SUMIFS('1. Maint Account'!T:T,'1. Maint Account'!Q:Q,'OPEX Budget'!O12,'1. Maint Account'!P:P,'OPEX Budget'!$P$3,'1. Maint Account'!G:G,"Q3") -> 94400
P13: =SUM(P4:P12) -> 20096271 | Q13: =SUM(Q4:Q12) -> 19894863 | R13: =SUM(R4:R12) -> 13401156
A14: Water & Sewage | B14: 3696782 | C14: Q1
A15: Civil & Lifts | B15: 1615896 | C15: Q1
A16: Electrical | B16: 5898302 | C16: Q1
A17: Housekeeping & Waste | B17: 3087334 | C17: Q1
A18: ClubHouse | B18: 72345 | C18: Q1
A19: Safety & Security | B19: 7288876 | C19: Q1
A20: Landscaping & ERT | B20: 1742477 | C20: Q1
A21: Estate Management | B21: 1585633 | C21: Q1
A22: Finance & Accounts | B22: 322887 | C22: Q1
A23: Total | B23: =SUM(B14:B22) -> 25310532 | C23: Q1
A25: Water & Sewage | B25: 4496127 | C25: Q2
A26: Civil & Lifts | B26: 1565877.4 | C26: Q2
A27: Electrical | B27: 4885353.1 | C27: Q2
A28: Housekeeping & Waste | B28: 1491303.6 | C28: Q2
A29: ClubHouse | B29: 29002.1 | C29: Q2
A30: Safety & Security | B30: 7407870.4 | C30: Q2
A31: Landscaping & ERT | B31: 1770923.3 | C31: Q2
A32: Estate Management | B32: 886861.16 | C32: Q2
A33: Finance & Accounts | B33: 347848.68 | C33: Q2
A34: Total | B34: =SUM(B25:B33) -> 22881167 | C34: Q2
A36: Water & Sewage | B36: 4085895.8 | C36: Q4
A37: Civil & Lifts | B37: 1906166.3 | C37: Q4
A38: Electrical | B38: 4895833 | C38: Q4
A39: Housekeeping & Waste | B39: 3557939 | C39: Q4
A40: ClubHouse | B40: 82592.665 | C40: Q4
A41: Safety & Security | B41: 6695499.6 | C41: Q4
A42: Landscaping & ERT | B42: 1756111.3 | C42: Q4
...

Sheet Capex Budget
A1: Nature | B1: Amount | C1: Quarter
A2: Fire Alarm Installation | B2: 0 | C2: Q1
A3: Park-plus Services | B3: 0 | C3: Q1
A4: West gate Entry and Exit Civil Works | B4: 0 | C4: Q1
A5: Screw Press Machine for STP-Blue | B5: 0 | C5: Q1
A6: Borewell | B6: 0 | C6: Q1
A7: RWH Works | B7: 0 | C7: Q1
A8: STP Water Cutter Pump | B8: 0 | C8: Q1
A9: Clubhouse Terrace & Swimming Pool water work | B9: 0 | C9: Q1
A10: External Precast Compound wall | B10: 0 | C10: Q1
A11: Lift/UPS Batteries | B11: 0 | C11: Q1
A12: CH - Civil Work | B12: 0 | C12: Q1
A13: East Wall Civil Works | B13: 0 | C13: Q1
... A38: Dumbells for Gym | B38: 0 | C38: Q3
